{"trial_id": "0", "hyperparameters": {"space": [{"class_name": "Int", "config": {"name": "conv_1_filter", "default": null, "conditions": [], "min_value": 32, "max_value": 128, "step": 16, "sampling": "linear"}}, {"class_name": "Choice", "config": {"name": "conv_1_kernel", "default": 3, "conditions": [], "values": [3, 5], "ordered": true}}, {"class_name": "Int", "config": {"name": "conv_2_filter", "default": null, "conditions": [], "min_value": 32, "max_value": 64, "step": 16, "sampling": "linear"}}, {"class_name": "Choice", "config": {"name": "conv_2_kernel", "default": 3, "conditions": [], "values": [3, 5], "ordered": true}}, {"class_name": "Int", "config": {"name": "dense_1_units", "default": null, "conditions": [], "min_value": 32, "max_value": 128, "step": 16, "sampling": "linear"}}, {"class_name": "Choice", "config": {"name": "learning_rate", "default": 0.01, "conditions": [], "values": [0.01, 0.001], "ordered": true}}], "values": {"conv_1_filter": 96, "conv_1_kernel": 3, "conv_2_filter": 64, "conv_2_kernel": 3, "dense_1_units": 112, "learning_rate": 0.01}}, "metrics": {"metrics": {}}, "score": null, "best_step": 0, "status": "FAILED", "message": "Traceback (most recent call last):\n  File \"C:\\Users\\Ashish Vora\\anaconda3\\lib\\site-packages\\keras_tuner\\src\\engine\\base_tuner.py\", line 273, in _try_run_and_update_trial\n    self._run_and_update_trial(trial, *fit_args, **fit_kwargs)\n  File \"C:\\Users\\Ashish Vora\\anaconda3\\lib\\site-packages\\keras_tuner\\src\\engine\\base_tuner.py\", line 238, in _run_and_update_trial\n    results = self.run_trial(trial, *fit_args, **fit_kwargs)\n  File \"C:\\Users\\Ashish Vora\\anaconda3\\lib\\site-packages\\keras_tuner\\src\\engine\\tuner.py\", line 314, in run_trial\n    obj_value = self._build_and_fit_model(trial, *args, **copied_kwargs)\n  File \"C:\\Users\\Ashish Vora\\anaconda3\\lib\\site-packages\\keras_tuner\\src\\engine\\tuner.py\", line 233, in _build_and_fit_model\n    results = self.hypermodel.fit(hp, model, *args, **kwargs)\n  File \"C:\\Users\\Ashish Vora\\anaconda3\\lib\\site-packages\\keras_tuner\\src\\engine\\hypermodel.py\", line 149, in fit\n    return model.fit(*args, **kwargs)\n  File \"C:\\Users\\Ashish Vora\\anaconda3\\lib\\site-packages\\keras\\src\\utils\\traceback_utils.py\", line 70, in error_handler\n    raise e.with_traceback(filtered_tb) from None\n  File \"C:\\Users\\Ashish Vora\\anaconda3\\lib\\site-packages\\tensorflow\\python\\eager\\execute.py\", line 53, in quick_execute\n    tensors = pywrap_tfe.TFE_Py_Execute(ctx._handle, device_name, op_name,\ntensorflow.python.framework.errors_impl.InvalidArgumentError: Graph execution error:\n\nDetected at node sparse_categorical_crossentropy/SparseSoftmaxCrossEntropyWithLogits/SparseSoftmaxCrossEntropyWithLogits defined at (most recent call last):\n  File \"C:\\Users\\Ashish Vora\\anaconda3\\lib\\runpy.py\", line 196, in _run_module_as_main\n\n  File \"C:\\Users\\Ashish Vora\\anaconda3\\lib\\runpy.py\", line 86, in _run_code\n\n  File \"C:\\Users\\Ashish Vora\\anaconda3\\lib\\site-packages\\ipykernel_launcher.py\", line 17, in <module>\n\n  File \"C:\\Users\\Ashish Vora\\anaconda3\\lib\\site-packages\\traitlets\\config\\application.py\", line 992, in launch_instance\n\n  File \"C:\\Users\\Ashish Vora\\anaconda3\\lib\\site-packages\\ipykernel\\kernelapp.py\", line 711, in start\n\n  File \"C:\\Users\\Ashish Vora\\anaconda3\\lib\\site-packages\\tornado\\platform\\asyncio.py\", line 199, in start\n\n  File \"C:\\Users\\Ashish Vora\\anaconda3\\lib\\asyncio\\base_events.py\", line 603, in run_forever\n\n  File \"C:\\Users\\Ashish Vora\\anaconda3\\lib\\asyncio\\base_events.py\", line 1906, in _run_once\n\n  File \"C:\\Users\\Ashish Vora\\anaconda3\\lib\\asyncio\\events.py\", line 80, in _run\n\n  File \"C:\\Users\\Ashish Vora\\anaconda3\\lib\\site-packages\\ipykernel\\kernelbase.py\", line 510, in dispatch_queue\n\n  File \"C:\\Users\\Ashish Vora\\anaconda3\\lib\\site-packages\\ipykernel\\kernelbase.py\", line 499, in process_one\n\n  File \"C:\\Users\\Ashish Vora\\anaconda3\\lib\\site-packages\\ipykernel\\kernelbase.py\", line 406, in dispatch_shell\n\n  File \"C:\\Users\\Ashish Vora\\anaconda3\\lib\\site-packages\\ipykernel\\kernelbase.py\", line 729, in execute_request\n\n  File \"C:\\Users\\Ashish Vora\\anaconda3\\lib\\site-packages\\ipykernel\\ipkernel.py\", line 411, in do_execute\n\n  File \"C:\\Users\\Ashish Vora\\anaconda3\\lib\\site-packages\\ipykernel\\zmqshell.py\", line 531, in run_cell\n\n  File \"C:\\Users\\Ashish Vora\\anaconda3\\lib\\site-packages\\IPython\\core\\interactiveshell.py\", line 2961, in run_cell\n\n  File \"C:\\Users\\Ashish Vora\\anaconda3\\lib\\site-packages\\IPython\\core\\interactiveshell.py\", line 3016, in _run_cell\n\n  File \"C:\\Users\\Ashish Vora\\anaconda3\\lib\\site-packages\\IPython\\core\\async_helpers.py\", line 129, in _pseudo_sync_runner\n\n  File \"C:\\Users\\Ashish Vora\\anaconda3\\lib\\site-packages\\IPython\\core\\interactiveshell.py\", line 3221, in run_cell_async\n\n  File \"C:\\Users\\Ashish Vora\\anaconda3\\lib\\site-packages\\IPython\\core\\interactiveshell.py\", line 3400, in run_ast_nodes\n\n  File \"C:\\Users\\Ashish Vora\\anaconda3\\lib\\site-packages\\IPython\\core\\interactiveshell.py\", line 3460, in run_code\n\n  File \"C:\\Users\\Ashish Vora\\AppData\\Local\\Temp\\ipykernel_15236\\1054800787.py\", line 1, in <module>\n\n  File \"C:\\Users\\Ashish Vora\\anaconda3\\lib\\site-packages\\keras_tuner\\src\\engine\\base_tuner.py\", line 233, in search\n\n  File \"C:\\Users\\Ashish Vora\\anaconda3\\lib\\site-packages\\keras_tuner\\src\\engine\\base_tuner.py\", line 273, in _try_run_and_update_trial\n\n  File \"C:\\Users\\Ashish Vora\\anaconda3\\lib\\site-packages\\keras_tuner\\src\\engine\\base_tuner.py\", line 238, in _run_and_update_trial\n\n  File \"C:\\Users\\Ashish Vora\\anaconda3\\lib\\site-packages\\keras_tuner\\src\\engine\\tuner.py\", line 314, in run_trial\n\n  File \"C:\\Users\\Ashish Vora\\anaconda3\\lib\\site-packages\\keras_tuner\\src\\engine\\tuner.py\", line 233, in _build_and_fit_model\n\n  File \"C:\\Users\\Ashish Vora\\anaconda3\\lib\\site-packages\\keras_tuner\\src\\engine\\hypermodel.py\", line 149, in fit\n\n  File \"C:\\Users\\Ashish Vora\\anaconda3\\lib\\site-packages\\keras\\src\\utils\\traceback_utils.py\", line 65, in error_handler\n\n  File \"C:\\Users\\Ashish Vora\\anaconda3\\lib\\site-packages\\keras\\src\\engine\\training.py\", line 1807, in fit\n\n  File \"C:\\Users\\Ashish Vora\\anaconda3\\lib\\site-packages\\keras\\src\\engine\\training.py\", line 1401, in train_function\n\n  File \"C:\\Users\\Ashish Vora\\anaconda3\\lib\\site-packages\\keras\\src\\engine\\training.py\", line 1384, in step_function\n\n  File \"C:\\Users\\Ashish Vora\\anaconda3\\lib\\site-packages\\keras\\src\\engine\\training.py\", line 1373, in run_step\n\n  File \"C:\\Users\\Ashish Vora\\anaconda3\\lib\\site-packages\\keras\\src\\engine\\training.py\", line 1151, in train_step\n\n  File \"C:\\Users\\Ashish Vora\\anaconda3\\lib\\site-packages\\keras\\src\\engine\\training.py\", line 1209, in compute_loss\n\n  File \"C:\\Users\\Ashish Vora\\anaconda3\\lib\\site-packages\\keras\\src\\engine\\compile_utils.py\", line 277, in __call__\n\n  File \"C:\\Users\\Ashish Vora\\anaconda3\\lib\\site-packages\\keras\\src\\losses.py\", line 143, in __call__\n\n  File \"C:\\Users\\Ashish Vora\\anaconda3\\lib\\site-packages\\keras\\src\\losses.py\", line 270, in call\n\n  File \"C:\\Users\\Ashish Vora\\anaconda3\\lib\\site-packages\\keras\\src\\losses.py\", line 2454, in sparse_categorical_crossentropy\n\n  File \"C:\\Users\\Ashish Vora\\anaconda3\\lib\\site-packages\\keras\\src\\backend.py\", line 5775, in sparse_categorical_crossentropy\n\nlogits and labels must have the same first dimension, got logits shape [32,10] and labels shape [320]\n\t [[{{node sparse_categorical_crossentropy/SparseSoftmaxCrossEntropyWithLogits/SparseSoftmaxCrossEntropyWithLogits}}]] [Op:__inference_train_function_1624]\n"}